<?xml version="1.0" ?>
<!-- =================================================================================== -->
<!-- |    This document was autogenerated by xacro from xacro/teststand.urdf.xacro     | -->
<!-- |    EDITING THIS FILE BY HAND IS NOT RECOMMENDED                                 | -->
<!-- =================================================================================== -->
<robot name="teststand" xmlns:controller="http://playerstage.sourceforge.net/gazebo/xmlschema/#controller" xmlns:interface="http://playerstage.sourceforge.net/gazebo/xmlschema/#interface" xmlns:sensor="http://playerstage.sourceforge.net/gazebo/xmlschema/#sensor" xmlns:xacro="http://playerstage.sourceforge.net/gazebo/xmlschema/#interface">
  <link name="world"/>
  <joint name="fixed_joint" type="fixed">
    <parent link="world"/>
    <child link="root"/>
  </joint>
  <link name="root"/>
  <joint name="joint_z" type="prismatic">
    <parent link="root"/>
    <child link="base_link"/>
    <limit effort="1000" lower="-10" upper="10" velocity="100000"/>
    <axis xyz="0 0 1"/>
    <origin rpy="0 0 0" xyz="0 0 0"/>
  </joint>
  <link name="base_link">
    <inertial>
      <origin rpy="0 0 0" xyz="0 0 0.0"/>
      <mass value="0.485"/>
      <inertia ixx="0.000808333333333" ixy="0" ixz="0" iyy="0.00202083333333" iyz="0" izz="0.00202083333333"/>
    </inertial>
    <visual>
      <origin rpy="0 0 0" xyz="0 0 0.05"/>
      <geometry>
        <mesh filename="meshes/cube.obj" scale="0.2 0.1 0.1"/>
      </geometry>
      <material name="white">
        <color rgba="1 1 1 1"/>
      </material>
    </visual>
    <collision>
      <origin rpy="0 0 0" xyz="0 0 0"/>
      <geometry>
        <box size="0.2 0.1 0.1"/>
      </geometry>
    </collision>
  </link>
  <joint name="HFE" type="revolute">
    <parent link="base_link"/>
    <child link="upperleg"/>
    <limit effort="2.5" lower="-10" upper="10" velocity="100000"/>
    <axis xyz="0 1 0"/>
    <origin rpy="0 0 0" xyz="0.0 0.0 0"/>
    <dynamics damping="0.0" friction="0.0"/>
  </joint>
  <link name="upperleg">
    <visual>
      <origin rpy="0 0 0" xyz="0 0 -0.08"/>
      <geometry>
        <!-- <cylinder length="${upper_leg_length}" radius="${upper_leg_radius}"/> -->
        <mesh filename="meshes/cylinder.obj" scale="0.025 0.025 0.16"/>
      </geometry>
      <material name="grey">
        <color rgba="1 1 1 1"/>
      </material>
    </visual>
    <collision>
      <origin rpy="0 0 0" xyz="0 0 -0.08"/>
      <geometry>
        <cylinder length="0.16" radius="0.025"/>
      </geometry>
    </collision>
    <inertial>
      <origin rpy="0 0 0" xyz="0 0 -0.0793"/>
      <mass value="0.162"/>
      <inertia ixx="0.000469609" ixy="0.0" ixz="0.0" iyy="0.000469609" iyz="0.0" izz="1e-6"/>
    </inertial>
  </link>
  <joint name="KFE" type="revolute">
    <parent link="upperleg"/>
    <child link="shank"/>
    <limit effort="2.5" velocity="1000000"/>
    <axis xyz="0 1 0"/>
    <origin rpy="0 0 0" xyz="0 0 -0.16"/>
    <dynamics damping="0.0" friction="0.0"/>
  </joint>
  <link name="shank">
    <contact>
      <lateral_friction value="1.0"/>
      <restitution value="0.5"/>
    </contact>
    <visual>
      <origin rpy="0 0 0" xyz="0 0 -0.08"/>
      <geometry>
        <!-- <cylinder length="${upper_leg_length}" radius="${upper_leg_radius}"/> -->
        <mesh filename="meshes/cylinder.obj" scale="0.025 0.025 0.16"/>
      </geometry>
      <material name="grey">
        <color rgba="1 1 1 1"/>
      </material>
    </visual>
    <collision>
      <origin rpy="0 0 0" xyz="0 0 -0.08"/>
      <geometry>
        <cylinder length="0.16" radius="0.025"/>
      </geometry>
    </collision>
    <inertial>
      <origin rpy="0 0 0" xyz="0 0 -0.0756"/>
      <mass value="0.021"/>
      <inertia ixx="0.000087575" ixy="0.0" ixz="0.0" iyy="0.000087575" iyz="0.0" izz="1e-6"/>
    </inertial>
  </link>
  <joint name="END" type="fixed">
    <parent link="shank"/>
    <child link="contact"/>
    <origin rpy="0 0 0" xyz="0 0 -0.16"/>
  </joint>
  <link name="contact">
    <contact>
      <lateral_friction value="1.0"/>
      <restitution value="0.5"/>
    </contact>
    <visual>
      <origin rpy="0 0 0" xyz="0 0 0"/>
      <geometry>
        <!-- <sphere radius="${upper_leg_radius}"/> -->
        <mesh filename="meshes/sphere.obj" scale="0.025 0.025 0.025"/>
      </geometry>
      <material name="red">
        <color rgba="1. 0. 0. 1."/>
      </material>
    </visual>
    <collision>
      <origin rpy="0 0 0" xyz="0 0 0"/>
      <geometry>
        <sphere radius="0.025"/>
      </geometry>
    </collision>
    <inertial>
      <mass value="0.01"/>
      <inertia ixx="0." ixy="0.0" ixz="0.0" iyy="0." iyz="0.0" izz="0."/>
    </inertial>
  </link>
</robot>
